Workbook

Sheet BOM
A1: Description | B1: Amount | C1: Comments | D1: Link buy | E1: Link info | F1: Piece price | G1: Shipping | H1: Total | I1: ="|"&A1&"|"&B1&"|"&C1&"|"&D1&"|"&E1&"|"&F1&"|"&G1&"|"&H1&"|" -> |Description|Amount|Comments|Link buy|Link info|Piece price|Shipping|Total|
A2: --- | B2: --- | C2: --- | D2: --- | E2: --- | F2: --- | G2: --- | H2: --- | I2: ="|"&A2&"|"&B2&"|"&C2&"|"&D2&"|"&E2&"|"&F2&"|"&G2&"|"&H2&"|" -> |---|---|---|---|---|---|---|---|
A3: Peristaltic Pump,12V (We use zy-1000f5) | B3: 4 | C3: Only needed for carbonated liquids | D3: https://www.banggood.com/500mL-or-min-Large-Flow-Easy-To-Install-Peristaltic-Pump-12V-or-24V-Metering-Vacuum-Pump-Flat-Type-Aquarium-p-1749029.html https://nl.aliexpress.com/item/1005004441796531.html?spm=a2g0o.order_list.0.0.d52c79d2o45Zo0&gatewayAdapt=glo2nld | E3: https://youtu.be/AMiXme4bMUk | F3: =(22.43*2+29.46*2)/4 -> 25.945 | G3: 1.62 | H3: =B3*F3+G3 -> 105.4 | I3: =IF(A3="","","|"&A3&"|"&B3&"|"&C3&"|"&IF(D3="","","[link]("&D3&")")&"|"&IF(E3=" ","",IF(F3="","","[link]("&E3&")"))&"|"&IF(F3="","",ROUND(F3,2))&"|"&IF(G3="","",ROUND(G3,2))&"|"&IF(H3="","",ROUND(H3,2))&"|") -> |Peristaltic Pump,12V (We use zy-1000f5)|4|Only needed for carbonated liquids|[link](https://www.banggood.com/500mL-or-min-Large-Flow-Easy-To-Install-Peristaltic-Pump-12V-or-24V-Metering-Vacuum-Pump-Flat-Type-Aquarium-p-1749029.html https://nl.aliexpress.com/item/1005004441796531.html?spm=a2g0o.order_list.0.0.d52c79d2o45Zo0&gatewayAdapt=glo2nld)|[link](https://youtu.be/AMiXme4bMUk)|25.95|1.62|105.4|
A4: Pullys | B4: 2 | D4: https://www.123-3d.nl/123-3D-GT2-Pulley-hoge-resolutie-met-lager-6-mm-riem-20-tanden-5-mm-as-zwart-i2546-t0.html | F4: 7.5 | G4: =4.95/7 -> 0.70714286 | H4: =B4*F4+G4 -> 15.707143 | I4: =IF(A4="","","|"&A4&"|"&B4&"|"&C4&"|"&IF(D4="","","[link]("&D4&")")&"|"&IF(E4=" ","",IF(F4="","","[link]("&E4&")"))&"|"&IF(F4="","",ROUND(F4,2))&"|"&IF(G4="","",ROUND(G4,2))&"|"&IF(H4="","",ROUND(H4,2))&"|") -> |Pullys|2||[link](https://www.123-3d.nl/123-3D-GT2-Pulley-hoge-resolutie-met-lager-6-mm-riem-20-tanden-5-mm-as-zwart-i2546-t0.html)||7.5|0.71|15.71|
A5: Motor pullys | B5: 2 | D5: https://www.123-3d.nl/123-3D-GT2-Pulley-hoge-resolutie-6-mm-riem-20-tanden-5-mm-as-zwart-400211009-i2547-t0.html | F5: 7.5 | G5: =4.95/7 -> 0.70714286 | H5: =B5*F5+G5 -> 15.707143 | I5: =IF(A5="","","|"&A5&"|"&B5&"|"&C5&"|"&IF(D5="","","[link]("&D5&")")&"|"&IF(E5=" ","",IF(F5="","","[link]("&E5&")"))&"|"&IF(F5="","",ROUND(F5,2))&"|"&IF(G5="","",ROUND(G5,2))&"|"&IF(H5="","",ROUND(H5,2))&"|") -> |Motor pullys|2||[link](https://www.123-3d.nl/123-3D-GT2-Pulley-hoge-resolutie-6-mm-riem-20-tanden-5-mm-as-zwart-400211009-i2547-t0.html)||7.5|0.71|15.71|
A6: Reininforced belt 6mm wide | B6: 1 | C6: 2.7m needed | D6: https://www.123-3d.nl/123-3D-GT2-timing-belt-6-mm-5-meter-i6541-t3046.html | F6: 21 | G6: =4.95/7 -> 0.70714286 | H6: =B6*F6+G6 -> 21.707143 | I6: =IF(A6="","","|"&A6&"|"&B6&"|"&C6&"|"&IF(D6="","","[link]("&D6&")")&"|"&IF(E6=" ","",IF(F6="","","[link]("&E6&")"))&"|"&IF(F6="","",ROUND(F6,2))&"|"&IF(G6="","",ROUND(G6,2))&"|"&IF(H6="","",ROUND(H6,2))&"|") -> |Reininforced belt 6mm wide|1|2.7m needed|[link](https://www.123-3d.nl/123-3D-GT2-timing-belt-6-mm-5-meter-i6541-t3046.html)||21|0.71|21.71|
A7: Leadscrew moer, TR8x8 | B7: 1 | D7: https://www.123-3d.nl/123-3D-Leadscrew-moer-TR8x8-i1560-t0.html | F7: 6 | G7: =4.95/7 -> 0.70714286 | H7: =B7*F7+G7 -> 6.7071429 | I7: =IF(A7="","","|"&A7&"|"&B7&"|"&C7&"|"&IF(D7="","","[link]("&D7&")")&"|"&IF(E7=" ","",IF(F7="","","[link]("&E7&")"))&"|"&IF(F7="","",ROUND(F7,2))&"|"&IF(G7="","",ROUND(G7,2))&"|"&IF(H7="","",ROUND(H7,2))&"|") -> |Leadscrew moer, TR8x8|1||[link](https://www.123-3d.nl/123-3D-Leadscrew-moer-TR8x8-i1560-t0.html)||6|0.71|6.71|
A8: Leadscrew, TR8x8, 8 mm | B8: 1 | C8: This one is 30cm, unsure what we need | D8: https://www.123-3d.nl/123-3D-Leadscrew-TR8x8-8-mm-30-cm-i1558-t0.html | F8: 9.5 | G8: =4.95/7 -> 0.70714286 | H8: =B8*F8+G8 -> 10.207143 | I8: =IF(A8="","","|"&A8&"|"&B8&"|"&C8&"|"&IF(D8="","","[link]("&D8&")")&"|"&IF(E8=" ","",IF(F8="","","[link]("&E8&")"))&"|"&IF(F8="","",ROUND(F8,2))&"|"&IF(G8="","",ROUND(G8,2))&"|"&IF(H8="","",ROUND(H8,2))&"|") -> |Leadscrew, TR8x8, 8 mm|1|This one is 30cm, unsure what we need|[link](https://www.123-3d.nl/123-3D-Leadscrew-TR8x8-8-mm-30-cm-i1558-t0.html)||9.5|0.71|10.21|
A9: Staaf as glad 8 m | B9: 1 | C9: This one is 100cm, unsure what we need | D9: https://www.123-3d.nl/123-3D-Staaf-as-glad-8-mm-x-100-cm-voor-X-of-Y-as-i56-t0.html | F9: 3.75 | G9: =4.95/7 -> 0.70714286 | H9: =B9*F9+G9 -> 4.4571429 | I9: =IF(A9="","","|"&A9&"|"&B9&"|"&C9&"|"&IF(D9="","","[link]("&D9&")")&"|"&IF(E9=" ","",IF(F9="","","[link]("&E9&")"))&"|"&IF(F9="","",ROUND(F9,2))&"|"&IF(G9="","",ROUND(G9,2))&"|"&IF(H9="","",ROUND(H9,2))&"|") -> |Staaf as glad 8 m|1|This one is 100cm, unsure what we need|[link](https://www.123-3d.nl/123-3D-Staaf-as-glad-8-mm-x-100-cm-voor-X-of-Y-as-i56-t0.html)||3.75|0.71|4.46|
A10: Flexibele motor koppeling 5 mm - 8 mm | B10: 1 | D10: https://www.123-3d.nl/123-3D-Flexibele-motor-koppeling-5-mm-8-mm-i342-t0.html | F10: 4.5 | G10: =4.95/7 -> 0.70714286 | H10: =B10*F10+G10 -> 5.2071429 | I10: =IF(A10="","","|"&A10&"|"&B10&"|"&C10&"|"&IF(D10="","","[link]("&D10&")")&"|"&IF(E10=" ","",IF(F10="","","[link]("&E10&")"))&"|"&IF(F10="","",ROUND(F10,2))&"|"&IF(G10="","",ROUND(G10,2))&"|"&IF(H10="","",ROUND(H10,2))&"|") -> |Flexibele motor koppeling 5 mm - 8 mm|1||[link](https://www.123-3d.nl/123-3D-Flexibele-motor-koppeling-5-mm-8-mm-i342-t0.html)||4.5|0.71|5.21|
A11: Frame end caps 2020 (3d print) | B11: 10 | C11: Print in black | E11: https://www.thingiverse.com/thing:2393904 | F11: 0.02 | G11: 0 | H11: =B11*F11+G11 -> 0.2 | I11: =IF(A11="","","|"&A11&"|"&B11&"|"&C11&"|"&IF(D11="","","[link]("&D11&")")&"|"&IF(E11=" ","",IF(F11="","","[link]("&E11&")"))&"|"&IF(F11="","",ROUND(F11,2))&"|"&IF(G11="","",ROUND(G11,2))&"|"&IF(H11="","",ROUND(H11,2))&"|") -> |Frame end caps 2020 (3d print)|10|Print in black||[link](https://www.thingiverse.com/thing:2393904)|0.02|0|0.2|
A12: Drink dispensers (6 way) | B12: 2 | C12: Spraypaint black | D12: https://www.bol.com/nl/nl/p/white-rhinoceros-drank-dispenser-bar-butler-shots-muurdispenser-voor-6-flessen/9300000007705748/?Referrer=ENTcli_order_confirmation2008093611 | F12: 38.95 | G12: 0 | H12: =B12*F12+G12 -> 77.9 | I12: =IF(A12="","","|"&A12&"|"&B12&"|"&C12&"|"&IF(D12="","","[link]("&D12&")")&"|"&IF(E12=" ","",IF(F12="","","[link]("&E12&")"))&"|"&IF(F12="","",ROUND(F12,2))&"|"&IF(G12="","",ROUND(G12,2))&"|"&IF(H12="","",ROUND(H12,2))&"|") -> |Drink dispensers (6 way)|2|Spraypaint black|[link](https://www.bol.com/nl/nl/p/white-rhinoceros-drank-dispenser-bar-butler-shots-muurdispenser-voor-6-flessen/9300000007705748/?Referrer=ENTcli_order_confirmation2008093611)||38.95|0|77.9|
A13: V frame (black 1500mm) | B13: 2 | C13: Cut in sizes: 2x750 + 2x353.5 + 2x396.5mm | D13: https://www.ratrig.com/aluminium-profiles/vslot/v-slot-2020-637.html | F13: 12.54 | G13: 28.52 | H13: =B13*F13+G13 -> 53.6 | I13: =IF(A13="","","|"&A13&"|"&B13&"|"&C13&"|"&IF(D13="","","[link]("&D13&")")&"|"&IF(E13=" ","",IF(F13="","","[link]("&E13&")"))&"|"&IF(F13="","",ROUND(F13,2))&"|"&IF(G13="","",ROUND(G13,2))&"|"&IF(H13="","",ROUND(H13,2))&"|") -> |V frame (black 1500mm)|2|Cut in sizes: 2x750 + 2x353.5 + 2x396.5mm|[link](https://www.ratrig.com/aluminium-profiles/vslot/v-slot-2020-637.html)||12.54|28.52|53.6|
A14: Frame corner profiles | B14: 20 | D14: https://nl.aliexpress.com/item/1005003618509458.html | F14: =10.02/20 -> 0.501 | G14: 2.43 | H14: =B14*F14+G14 -> 12.45 | I14: =IF(A14="","","|"&A14&"|"&B14&"|"&C14&"|"&IF(D14="","","[link]("&D14&")")&"|"&IF(E14=" ","",IF(F14="","","[link]("&E14&")"))&"|"&IF(F14="","",ROUND(F14,2))&"|"&IF(G14="","",ROUND(G14,2))&"|"&IF(H14="","",ROUND(H14,2))&"|") -> |Frame corner profiles|20||[link](https://nl.aliexpress.com/item/1005003618509458.html)||0.5|2.43|12.45|
A15: Wood (Gamma) | B15: 1 | C15: 2x30x80cm | F15: 30.48 | G15: 0 | H15: =B15*F15+G15 -> 30.48 | I15: =IF(A15="","","|"&A15&"|"&B15&"|"&C15&"|"&IF(D15="","","[link]("&D15&")")&"|"&IF(E15=" ","",IF(F15="","","[link]("&E15&")"))&"|"&IF(F15="","",ROUND(F15,2))&"|"&IF(G15="","",ROUND(G15,2))&"|"&IF(H15="","",ROUND(H15,2))&"|") -> |Wood (Gamma)|1|2x30x80cm|||30.48|0|30.48|
A16: 16x2 LCD Display I2C | B16: 1 | D16: https://elektronicavoorjou.nl/product/16x2-lcd-wit-op-blauw-5v-met-i2c/ | F16: 9.95 | G16: 2.99 | H16: =B16*F16+G16 -> 12.94 | I16: =IF(A16="","","|"&A16&"|"&B16&"|"&C16&"|"&IF(D16="","","[link]("&D16&")")&"|"&IF(E16=" ","",IF(F16="","","[link]("&E16&")"))&"|"&IF(F16="","",ROUND(F16,2))&"|"&IF(G16="","",ROUND(G16,2))&"|"&IF(H16="","",ROUND(H16,2))&"|") -> |16x2 LCD Display I2C|1||[link](https://elektronicavoorjou.nl/product/16x2-lcd-wit-op-blauw-5v-met-i2c/)||9.95|2.99|12.94|
A17: M3x10 | B17: 50 | D17: https://www.indi.nl/nl-nl/p/Cilindrische-inbusbout-M3x10-12.9-zwart-DIN912-912310129B | F17: =8.62/50 -> 0.1724 | G17: =(95.72-87.32)/6 -> 1.4 | H17: =B17*F17+G17 -> 10.02 | I17: =IF(A17="","","|"&A17&"|"&B17&"|"&C17&"|"&IF(D17="","","[link]("&D17&")")&"|"&IF(E17=" ","",IF(F17="","","[link]("&E17&")"))&"|"&IF(F17="","",ROUND(F17,2))&"|"&IF(G17="","",ROUND(G17,2))&"|"&IF(H17="","",ROUND(H17,2))&"|") -> |M3x10|50||[link](https://www.indi.nl/nl-nl/p/Cilindrische-inbusbout-M3x10-12.9-zwart-DIN912-912310129B)||0.17|1.4|10.02|
A18: M3x30 | B18: 50 | D18: https://www.indi.nl/nl-nl/p/Cilindrische-inbusbout-M3x30-12.9-zwart-DIN912-912330129B | F18: =8.62/50 -> 0.1724 | G18: =(95.72-87.32)/6 -> 1.4 | H18: =B18*F18+G18 -> 10.02 | I18: =IF(A18="","","|"&A18&"|"&B18&"|"&C18&"|"&IF(D18="","","[link]("&D18&")")&"|"&IF(E18=" ","",IF(F18="","","[link]("&E18&")"))&"|"&IF(F18="","",ROUND(F18,2))&"|"&IF(G18="","",ROUND(G18,2))&"|"&IF(H18="","",ROUND(H18,2))&"|") -> |M3x30|50||[link](https://www.indi.nl/nl-nl/p/Cilindrische-inbusbout-M3x30-12.9-zwart-DIN912-912330129B)||0.17|1.4|10.02|
A19: M5x10 | B19: 50 | D19: https://www.indi.nl/nl-nl/p/Cilindrische-inbusbout-M5x10-12.9-zwart-DIN912-912510129B | F19: 0.18 | G19: =(95.72-87.32)/6 -> 1.4 | H19: =B19*F19+G19 -> 10.4 | I19: =IF(A19="","","|"&A19&"|"&B19&"|"&C19&"|"&IF(D19="","","[link]("&D19&")")&"|"&IF(E19=" ","",IF(F19="","","[link]("&E19&")"))&"|"&IF(F19="","",ROUND(F19,2))&"|"&IF(G19="","",ROUND(G19,2))&"|"&IF(H19="","",ROUND(H19,2))&"|") -> |M5x10|50||[link](https://www.indi.nl/nl-nl/p/Cilindrische-inbusbout-M5x10-12.9-zwart-DIN912-912510129B)||0.18|1.4|10.4|
A20: M5x20 | B20: 50 | D20: https://www.indi.nl/nl-nl/p/Cilindrische-inbusbout-M5x20-12.9-zwart-DIN912-912520129B | F20: 0.18 | G20: =(95.72-87.32)/6 -> 1.4 | H20: =B20*F20+G20 -> 10.4 | I20: =IF(A20="","","|"&A20&"|"&B20&"|"&C20&"|"&IF(D20="","","[link]("&D20&")")&"|"&IF(E20=" ","",IF(F20="","","[link]("&E20&")"))&"|"&IF(F20="","",ROUND(F20,2))&"|"&IF(G20="","",ROUND(G20,2))&"|"&IF(H20="","",ROUND(H20,2))&"|") -> |M5x20|50||[link](https://www.indi.nl/nl-nl/p/Cilindrische-inbusbout-M5x20-12.9-zwart-DIN912-912520129B)||0.18|1.4|10.4|
A21: M5x30 | B21: 50 | D21: https://www.indi.nl/nl-nl/p/Cilindrische-inbusbout-M5x30-12.9-zwart-DIN912-912530129B | F21: 0.18 | G21: =(95.72-87.32)/6 -> 1.4 | H21: =B21*F21+G21 -> 10.4 | I21: =IF(A21="","","|"&A21&"|"&B21&"|"&C21&"|"&IF(D21="","","[link]("&D21&")")&"|"&IF(E21=" ","",IF(F21="","","[link]("&E21&")"))&"|"&IF(F21="","",ROUND(F21,2))&"|"&IF(G21="","",ROUND(G21,2))&"|"&IF(H21="","",ROUND(H21,2))&"|") -> |M5x30|50||[link](https://www.indi.nl/nl-nl/p/Cilindrische-inbusbout-M5x30-12.9-zwart-DIN912-912530129B)||0.18|1.4|10.4|
A22: M5x40 | B22: 50 | D22: https://www.indi.nl/nl-nl/p/Cilindrische-inbusbout-M5x40-12.9-zwart-DIN912-912540129B | F22: 0.27 | G22: =8.41/6 -> 1.4016667 | H22: =B22*F22+G22 -> 14.901667 | I22: =IF(A22="","","|"&A22&"|"&B22&"|"&C22&"|"&IF(D22="","","[link]("&D22&")")&"|"&IF(E22=" ","",IF(F22="","","[link]("&E22&")"))&"|"&IF(F22="","",ROUND(F22,2))&"|"&IF(G22="","",ROUND(G22,2))&"|"&IF(H22="","",ROUND(H22,2))&"|") -> |M5x40|50||[link](https://www.indi.nl/nl-nl/p/Cilindrische-inbusbout-M5x40-12.9-zwart-DIN912-912540129B)||0.27|1.4|14.9|
A23: M5x50 | B23: 50 | D23: https://www.indi.nl/nl-nl/p/Cilindrische-inbusbout-M5X50-12.9-zwart-DIN912-912550129B | F23: 0.34 | G23: =8.41/6 -> 1.4016667 | H23: =B23*F23+G23 -> 18.401667 | I23: =IF(A23="","","|"&A23&"|"&B23&"|"&C23&"|"&IF(D23="","","[link]("&D23&")")&"|"&IF(E23=" ","",IF(F23="","","[link]("&E23&")"))&"|"&IF(F23="","",ROUND(F23,2))&"|"&IF(G23="","",ROUND(G23,2))&"|"&IF(H23="","",ROUND(H23,2))&"|") -> |M5x50|50||[link](https://www.indi.nl/nl-nl/p/Cilindrische-inbusbout-M5X50-12.9-zwart-DIN912-912550129B)||0.34|1.4|18.4|
A24: M5x60 | B24: 50 | D24: https://www.indi.nl/nl-nl/p/Cilindrische-inbusbout-M5x60-12.9-zwart-DIN912-912560129B | F24: =19.32/50 -> 0.3864 | G24: =(95.72-87.32)/6 -> 1.4 | H24: =B24*F24+G24 -> 20.72 | I24: =IF(A24="","","|"&A24&"|"&B24&"|"&C24&"|"&IF(D24="","","[link]("&D24&")")&"|"&IF(E24=" ","",IF(F24="","","[link]("&E24&")"))&"|"&IF(F24="","",ROUND(F24,2))&"|"&IF(G24="","",ROUND(G24,2))&"|"&IF(H24="","",ROUND(H24,2))&"|") -> |M5x60|50||[link](https://www.indi.nl/nl-nl/p/Cilindrische-inbusbout-M5x60-12.9-zwart-DIN912-912560129B)||0.39|1.4|20.72|
A25: M5x80 | B25: 50 | D25: https://www.indi.nl/nl-nl/p/Cilindrische-inbusbout-M5x80-12.9-zwart-DIN912-912580129B | F25: =41.76/50 -> 0.8352 | G25: =(95.72-87.32)/6 -> 1.4 | H25: =B25*F25+G25 -> 43.16 | I25: =IF(A25="","","|"&A25&"|"&B25&"|"&C25&"|"&IF(D25="","","[link]("&D25&")")&"|"&IF(E25=" ","",IF(F25="","","[link]("&E25&")"))&"|"&IF(F25="","",ROUND(F25,2))&"|"&IF(G25="","",ROUND(G25,2))&"|"&IF(H25="","",ROUND(H25,2))&"|") -> |M5x80|50||[link](https://www.indi.nl/nl-nl/p/Cilindrische-inbusbout-M5x80-12.9-zwart-DIN912-912580129B)||0.84|1.4|43.16|
A26: Moer | B26: 200 | D26: https://www.indi.nl/nl-nl/p/Zeskantmoer-M5-klasse-8-verzinkt-DIN934-9345P100 | F26: 0.05 | G26: =(95.72-87.32)/6 -> 1.4 | H26: =B26*F26+G26 -> 11.4 | I26: =IF(A26="","","|"&A26&"|"&B26&"|"&C26&"|"&IF(D26="","","[link]("&D26&")")&"|"&IF(E26=" ","",IF(F26="","","[link]("&E26&")"))&"|"&IF(F26="","",ROUND(F26,2))&"|"&IF(G26="","",ROUND(G26,2))&"|"&IF(H26="","",ROUND(H26,2))&"|") -> |Moer|200||[link](https://www.indi.nl/nl-nl/p/Zeskantmoer-M5-klasse-8-verzinkt-DIN934-9345P100)||0.05|1.4|11.4|
A27: Borgmoer | B27: 8 | D27: https://www.gamma.nl/assortiment/gamma-borgmoer-m5-rvs-8-stuks/p/B458288 | F27: =2.79/8 -> 0.34875 | G27: 0 | H27: =B27*F27+G27 -> 2.79 | I27: =IF(A27="","","|"&A27&"|"&B27&"|"&C27&"|"&IF(D27="","","[link]("&D27&")")&"|"&IF(E27=" ","",IF(F27="","","[link]("&E27&")"))&"|"&IF(F27="","",ROUND(F27,2))&"|"&IF(G27="","",ROUND(G27,2))&"|"&IF(H27="","",ROUND(H27,2))&"|") -> |Borgmoer|8||[link](https://www.gamma.nl/assortiment/gamma-borgmoer-m5-rvs-8-stuks/p/B458288)||0.35|0|2.79|
A28: V-slot wheels | B28: 11 | F28: =7.12/10 -> 0.712 | G28: 0 | H28: =B28*F28+G28 -> 7.832 | I28: =IF(A28="","","|"&A28&"|"&B28&"|"&C28&"|"&IF(D28="","","[link]("&D28&")")&"|"&IF(E28=" ","",IF(F28="","","[link]("&E28&")"))&"|"&IF(F28="","",ROUND(F28,2))&"|"&IF(G28="","",ROUND(G28,2))&"|"&IF(H28="","",ROUND(H28,2))&"|") -> |V-slot wheels|11||||0.71|0|7.83|
A29: JLC PCB | B29: 5 | C29: (minimum 5 pieces) | F29: 1.44 | G29: 0 | H29: =B29*F29+G29 -> 7.2 | I29: =IF(A29="","","|"&A29&"|"&B29&"|"&C29&"|"&IF(D29="","","[link]("&D29&")")&"|"&IF(E29=" ","",IF(F29="","","[link]("&E29&")"))&"|"&IF(F29="","",ROUND(F29,2))&"|"&IF(G29="","",ROUND(G29,2))&"|"&IF(H29="","",ROUND(H29,2))&"|") -> |JLC PCB|5|(minimum 5 pieces)||[link]()|1.44|0|7.2|
A30: PCB-TMC2208 motor controller | B30: 3 | C30: X, Y, Z | D30: https://nl.aliexpress.com/item/1005004014058136.html | E30: https://wiki.fysetc.com/TMC2208/ | F30: =(20.42+4.44)/10 -> 2.486 | G30: 0 | H30: =B30*F30+G30 -> 7.458 | I30: =IF(A30="","","|"&A30&"|"&B30&"|"&C30&"|"&IF(D30="","","[link]("&D30&")")&"|"&IF(E30=" ","",IF(F30="","","[link]("&E30&")"))&"|"&IF(F30="","",ROUND(F30,2))&"|"&IF(G30="","",ROUND(G30,2))&"|"&IF(H30="","",ROUND(H30,2))&"|") -> |PCB-TMC2208 motor controller|3|X, Y, Z|[link](https://nl.aliexpress.com/item/1005004014058136.html)|[link](https://wiki.fysetc.com/TMC2208/)|2.49|0|7.46|
A31: Microswitch | B31: 3 | C31: Used for homing, not as limit switch | D31: https://www.hobbyelectronica.nl/product/endstop-mechanisch-microswitch/ | F31: 0.95 | G31: 3.45 | H31: =B31*F31+G31 -> 6.3 | I31: =IF(A31="","","|"&A31&"|"&B31&"|"&C31&"|"&IF(D31="","","[link]("&D31&")")&"|"&IF(E31=" ","",IF(F31="","","[link]("&E31&")"))&"|"&IF(F31="","",ROUND(F31,2))&"|"&IF(G31="","",ROUND(G31,2))&"|"&IF(H31="","",ROUND(H31,2))&"|") -> |Microswitch|3|Used for homing, not as limit switch|[link](https://www.hobbyelectronica.nl/product/endstop-mechanisch-microswitch/)||0.95|3.45|6.3|
A32: Tubing 5x7 | B32: 6 | D32: https://www.kiwi-electronics.com/nl/siliconen-slang-5x7mm-2-meter-10188 | F32: 1.95 | G32: 2.95 | H32: =B32*F32+G32 -> 14.65 | I32: =IF(A32="","","|"&A32&"|"&B32&"|"&C32&"|"&IF(D32="","","[link]("&D32&")")&"|"&IF(E32=" ","",IF(F32="","","[link]("&E32&")"))&"|"&IF(F32="","",ROUND(F32,2))&"|"&IF(G32="","",ROUND(G32,2))&"|"&IF(H32="","",ROUND(H32,2))&"|") -> |Tubing 5x7|6||[link](https://www.kiwi-electronics.com/nl/siliconen-slang-5x7mm-2-meter-10188)||1.95|2.95|14.65|
A33: Tubing 2x4 | B33: 14 | D33: https://www.slangenshop.nl/home/22-siliconen-slang-2-x-4-mm-.html | F33: =(30.15-7.95)/10 -> 2.22 | G33: 7.95 | H33: =B33*F33+G33 -> 39.03 | I33: =IF(A33="","","|"&A33&"|"&B33&"|"&C33&"|"&IF(D33="","","[link]("&D33&")")&"|"&IF(E33=" ","",IF(F33="","","[link]("&E33&")"))&"|"&IF(F33="","",ROUND(F33,2))&"|"&IF(G33="","",ROUND(G33,2))&"|"&IF(H33="","",ROUND(H33,2))&"|") -> |Tubing 2x4|14||[link](https://www.slangenshop.nl/home/22-siliconen-slang-2-x-4-mm-.html)||2.22|7.95|39.03|
A34: Tubing 3x5 | B34: 7 | D34: https://www.slangenshop.nl/home/25-siliconen-slang-3-x-5-mm-.html | F34: 3.88 | G34: 6.95 | H34: =B34*F34+G34 -> 34.11 | I34: =IF(A34="","","|"&A34&"|"&B34&"|"&C34&"|"&IF(D34="","","[link]("&D34&")")&"|"&IF(E34=" ","",IF(F34="","","[link]("&E34&")"))&"|"&IF(F34="","",ROUND(F34,2))&"|"&IF(G34="","",ROUND(G34,2))&"|"&IF(H34="","",ROUND(H34,2))&"|") -> |Tubing 3x5|7||[link](https://www.slangenshop.nl/home/25-siliconen-slang-3-x-5-mm-.html)||3.88|6.95|34.11|
A35: Tubing 4x6 | B35: 7 | D35: https://www.slangenshop.nl/home/24-siliconen-slang-4-x-6-mm-.html?search_query=Siliconen+slang+4&results=24 | F35: 3.81 | G35: 7.95 | H35: =B35*F35+G35 -> 34.62 | I35: =IF(A35="","","|"&A35&"|"&B35&"|"&C35&"|"&IF(D35="","","[link]("&D35&")")&"|"&IF(E35=" ","",IF(F35="","","[link]("&E35&")"))&"|"&IF(F35="","",ROUND(F35,2))&"|"&IF(G35="","",ROUND(G35,2))&"|"&IF(H35="","",ROUND(H35,2))&"|") -> |Tubing 4x6|7||[link](https://www.slangenshop.nl/home/24-siliconen-slang-4-x-6-mm-.html?search_query=Siliconen+slang+4&results=24)||3.81|7.95|34.62|
A36: 0826B 0.5-20N 8mm | B36: 1 | D36: https://www.aliexpress.com/item/1005004016711403.html?spm=a2g0o.cart.0.0.603638daNtRRN5&mp=1 | F36: =1.21*7.06 -> 8.5426 | H36: =B36*F36+G36 -> 8.5426 | I36: =IF(A36="","","|"&A36&"|"&B36&"|"&C36&"|"&IF(D36="","","[link]("&D36&")")&"|"&IF(E36=" ","",IF(F36="","","[link]("&E36&")"))&"|"&IF(F36="","",ROUND(F36,2))&"|"&IF(G36="","",ROUND(G36,2))&"|"&IF(H36="","",ROUND(H36,2))&"|") -> |0826B 0.5-20N 8mm|1||[link](https://www.aliexpress.com/item/1005004016711403.html?spm=a2g0o.cart.0.0.603638daNtRRN5&mp=1)||8.54||8.54|
A37: 1050B 4.5-50N 15mm | B37: 1 | D37: https://www.aliexpress.com/item/1005004016711403.html?spm=a2g0o.cart.0.0.603638daNtRRN5&mp=1 | F37: =1.21*13.52 -> 16.3592 | H37: =B37*F37+G37 -> 16.3592 | I37: =IF(A37="","","|"&A37&"|"&B37&"|"&C37&"|"&IF(D37="","","[link]("&D37&")")&"|"&IF(E37=" ","",IF(F37="","","[link]("&E37&")"))&"|"&IF(F37="","",ROUND(F37,2))&"|"&IF(G37="","",ROUND(G37,2))&"|"&IF(H37="","",ROUND(H37,2))&"|") -> |1050B 4.5-50N 15mm|1||[link](https://www.aliexpress.com/item/1005004016711403.html?spm=a2g0o.cart.0.0.603638daNtRRN5&mp=1)||16.36||16.36|
A38: Motion Film Pressure Sensor 100g | B38: 1 | D38: https://www.aliexpress.com/item/32878178151.html?spm=a2g0o.cart.0.0.603638daNtRRN5&mp=1 | F38: 1.31 | G38: =1.59/2 -> 0.795 | H38: =B38*F38+G38 -> 2.105 | I38: =IF(A38="","","|"&A38&"|"&B38&"|"&C38&"|"&IF(D38="","","[link]("&D38&")")&"|"&IF(E38=" ","",IF(F38="","","[link]("&E38&")"))&"|"&IF(F38="","",ROUND(F38,2))&"|"&IF(G38="","",ROUND(G38,2))&"|"&IF(H38="","",ROUND(H38,2))&"|") -> |Motion Film Pressure Sensor 100g|1||[link](https://www.aliexpress.com/item/32878178151.html?spm=a2g0o.cart.0.0.603638daNtRRN5&mp=1)||1.31|0.8|2.11|
A39: Motion Film Pressure Sensor 1kg | B39: 1 | D39: https://www.aliexpress.com/item/32878178151.html?spm=a2g0o.cart.0.0.603638daNtRRN5&mp=1 | F39: 1.31 | G39: =1.59/2 -> 0.795 | H39: =B39*F39+G39 -> 2.105 | I39: =IF(A39="","","|"&A39&"|"&B39&"|"&C39&"|"&IF(D39="","","[link]("&D39&")")&"|"&IF(E39=" ","",IF(F39="","","[link]("&E39&")"))&"|"&IF(F39="","",ROUND(F39,2))&"|"&IF(G39="","",ROUND(G39,2))&"|"&IF(H39="","",ROUND(H39,2))&"|") -> |Motion Film Pressure Sensor 1kg|1||[link](https://www.aliexpress.com/item/32878178151.html?spm=a2g0o.cart.0.0.603638daNtRRN5&mp=1)||1.31|0.8|2.11|
A40: Solenoid Valve 4.5mm inner 12V | B40: 1 | D40: https://www.aliexpress.com/item/1005005553905520.html?spm=a2g0o.cart.0.0.603638daNtRRN5&mp=1 | F40: 3.34 | G40: 3.61 | H40: =B40*F40+G40 -> 6.95 | I40: =IF(A40="","","|"&A40&"|"&B40&"|"&C40&"|"&IF(D40="","","[link]("&D40&")")&"|"&IF(E40=" ","",IF(F40="","","[link]("&E40&")"))&"|"&IF(F40="","",ROUND(F40,2))&"|"&IF(G40="","",ROUND(G40,2))&"|"&IF(H40="","",ROUND(H40,2))&"|") -> |Solenoid Valve 4.5mm inner 12V|1||[link](https://www.aliexpress.com/item/1005005553905520.html?spm=a2g0o.cart.0.0.603638daNtRRN5&mp=1)||3.34|3.61|6.95|
...

Sheet Pinout
A1: GPIO | B1: Input | C1: Output | D1: Notes
A2: 0 | B2: pulled up | C2: OK | D2: outputs PWM signal at boot | E2: NU | F2: was
A3: 1 | B3: TX pin | C3: OK | D3: debug output at boot | E3: TX
A4: 2 | B4: OK | C4: OK | D4: connected to on-board LED | E4: LED
A5: 3 | B5: OK | C5: RX pin | D5: HIGH at boot | E5: RX
A6: 4 | B6: OK | C6: OK | E6: PDO_X_Step
A7: 5 | B7: OK | C7: OK | D7: outputs PWM signal at boot | E7: PDI_X_Ref | F7: PDO_Y_Step
A8: 12 | B8: OK | C8: OK | D8: boot fail if pulled high | E8: PDO_Y_Step | F8: PDI_X_Ref
A9: 13 | B9: OK | C9: OK | E9: LED_PWM
A10: 14 | B10: OK | C10: OK | D10: outputs PWM signal at boot | E10: PDI_B
A11: 15 | B11: OK | C11: OK | D11: outputs PWM signal at boot | E11: PDI_Z_Ref | F11: PDO_X_Dir
A12: 16 | B12: OK | C12: OK | E12: PDO_Step_enable
A13: 17 | B13: OK | C13: OK | E13: PDO_Y_Dir
A14: 18 | B14: OK | C14: OK | E14: PDO_Z_Dir
A15: 19 | B15: OK | C15: OK | E15: PDO_Z_Step
A16: 21 | B16: OK | C16: OK | E16: I2C_SDA
A17: 22 | B17: OK | C17: OK | E17: I2C_SCL
A18: 23 | B18: OK | C18: OK | E18: PDO_X_Dir
A19: 25 | B19: OK | C19: OK | E19: PDO_Pump3
A20: 26 | B20: OK | C20: OK | E20: PDO_Pump4
A21: 27 | B21: OK | C21: OK | E21: PDI_Y_Ref | F21: PDI_A
A22: 32 | B22: OK | C22: OK | E22: PDO_Pump1
A23: 33 | B23: OK | C23: OK | E23: PDO_Pump2
A24: 34 | B24: OK | D24: input only | E24: PDI_A | F24: PDI_Y_Ref
A25: 35 | B25: OK | D25: input only | F25: PDI_Z_Ref
A26: 36 | B26: OK | D26: input only
A27: 39 | B27: OK | D27: input only | E27: PDI_S

Sheet Drinks
A1: Cocktail | B1: Color | C1: Ingredient 1 | D1: ml | E1: Ingredient 2 | F1: ml | G1: Ingredient 3 | H1: ml | I1: Ingredient 4 | J1: ml | K1: Ingredient 5 | L1: ml | M1: Ingredient 6 | N1: ml | O1: Ingredient 7 | P1: ml | Q1: Ingredient 8 | R1: ml | T1: ml total | U1: Glass
A2: Sex on the Beach | B2: bab34 | C2: #ice | D2: 0 | E2: Vodka | F2: 45 | G2: Peach Tree | H2: 45 | I2: Orange juice | J2: 135 | K2: #shake | L2: 0 | M2: Cranberry juice | N2: 30 | T2: =D2+F2+H2+J2+L2+N2+P2+R2 -> 255 | U2: Big
A3: Screwdriver | B3: e8d86d | C3: Vodka | D3: 45 | E3: Orange Juice | F3: 120 | G3: #stir | H3: 0 | T3: =D3+F3+H3+J3+L3+N3+P3+R3 -> 165 | U3: Medium
A4: Cosmopolitan Classic | B4: e81058 | C4: Vodka | D4: 23 | E4: Triple Sec | F4: 15 | G4: Cranberry juice | H4: 30 | I4: Lime juice | J4: 15 | K4: #shake | L4: 0 | T4: =D4+F4+H4+J4+L4+N4+P4+R4 -> 83 | U4: Rock
A5: Bay Breeze | B5: ff8400 | C5: Vodka | D5: 45 | E5: Pineapple juice | F5: 30 | G5: Cranberry juice | H5: 30 | I5: #stir | J5: 0 | T5: =D5+F5+H5+J5+L5+N5+P5+R5 -> 105 | U5: Rock
A6: Hole in One | B6: e3c532 | C6: #ice | D6: 0 | E6: Vodka | F6: 45 | G6: Cranberry juice | H6: 90 | I6: #stir | J6: 0 | K6: Orange juice | L6: 30 | T6: =D6+F6+H6+J6+L6+N6+P6+R6 -> 165 | U6: Medium
A7: Gimlet | B7: d5f5dd | C7: #crushed ice | D7: 0 | E7: Gin | F7: 90 | G7: Lime juice | H7: 30 | I7: #shake | J7: 0 | T7: =D7+F7+H7+J7+L7+N7+P7+R7 -> 120 | U7: Medium
A8: Black widow | B8: 800101 | C8: Vodka | D8: 30 | E8: Cranberry juice | F8: 30 | G8: Lemonade | H8: 30 | I8: #stir | J8: 0 | T8: =D8+F8+H8+J8+L8+N8+P8+R8 -> 90 | U8: Rock
A9: Gin Sidecar | B9: ced190 | C9: #crushed ice | D9: 0 | E9: Gin | F9: 60 | G9: Triple sec | H9: 30 | I9: Lemon juice | J9: 30 | K9: #shake | L9: 0 | T9: =D9+F9+H9+J9+L9+N9+P9+R9 -> 120 | U9: Medium
A10: Little Devil | B10: db4f40 | C10: #crushed ice | D10: 0 | E10: Gin | F10: 60 | G10: White rum | H10: 45 | I10: Triple sec | J10: 30 | K10: Lemon juice | L10: 30 | M10: #shake | N10: 0 | T10: =D10+F10+H10+J10+L10+N10+P10+R10 -> 165 | U10: Medium
A11: Hoola Hoop | B11: e3bc5b | C11: Gin | D11: 45 | E11: Orange Juice | F11: 30 | G11: Pineapple juice | H11: 30 | I11: #stir | J11: 0 | T11: =D11+F11+H11+J11+L11+N11+P11+R11 -> 105 | U11: Rock
A12: Hawaiian Cocktail | B12: edc766 | C12: Gin | D12: 60 | E12: Triple Sec | F12: 15 | G12: Pineapple juice | H12: 15 | I12: #shake | J12: 0 | T12: =D12+F12+H12+J12+L12+N12+P12+R12 -> 90 | U12: Rock
A13: Alpine Lemonade | B13: f5e4bc | C13: #ice | D13: 0 | E13: Vodka | F13: 30 | G13: Gin | H13: 30 | I13: Dark rum | J13: 30 | K13: Lemonade | L13: 60 | M13: Cranberry juice | N13: 60 | O13: #blend | P13: 0 | T13: =D13+F13+H13+J13+L13+N13+P13+R13 -> 210 | U13: Big
A14: Hula Hula | B14: baa165 | C14: #crushed ice | D14: 0 | E14: Gin | F14: 60 | G14: Orange Juice | H14: 30 | I14: Triple sec | J14: 5 | K14: #stir | L14: 0 | M14: #strain | N14: 0 | T14: =D14+F14+H14+J14+L14+N14+P14+R14 -> 95 | U14: Rock
A15: Judge J Cocktail | B15: ed775f | C15: #crushed ice | D15: 0 | E15: Gin | F15: 60 | G15: White rum | H15: 60 | I15: Lemon juice | J15: 30 | K15: Cranberry juice | L15: 10 | M15: #shake | N15: 0 | O15: #strain | P15: 0 | T15: =D15+F15+H15+J15+L15+N15+P15+R15 -> 160 | U15: Medium
A16: Rock Bottom | B16: f27157 | C16: Vodka | D16: 60 | E16: Pineapple juice | F16: 10 | G16: Gin | H16: 60 | I16: Lemon juice | J16: 10 | K16: Lime juice | L16: 10 | M16: #shake | N16: 0 | O16: Tequila | P16: 60 | T16: =D16+F16+H16+J16+L16+N16+P16+R16 -> 210 | U16: Big
A17: Beach Bum Shake | B17: e3a452 | C17: #crushed ice | D17: 0 | E17: Tequila | F17: 30 | G17: Orange Juice | H17: 60 | I17: Vodka | J17: 8 | K17: Triple sec | L17: 5 | M17: #shake | N17: 0 | O17: #strain | P17: 0 | T17: =D17+F17+H17+J17+L17+N17+P17+R17 -> 103 | U17: Rock
A18: Pussy popper | B18: db5740 | C18: #ice | D18: 0 | E18: Vodka | F18: 90 | G18: Triple sec | H18: 60 | I18: Cranberry juice | J18: 60 | K18: Orange juice | L18: 60 | M18: Grenadine syrup | N18: 5 | O18: #shake | P18: 0 | T18: =D18+F18+H18+J18+L18+N18+P18+R18 -> 275 | U18: Big
A19: Brass Monkey | B19: f5b922 | C19: Dark rum | D19: 15 | E19: Vodka | F19: 15 | G19: #stir | H19: 0 | I19: Orange juice | J19: 120 | K19: #shake | L19: 0 | T19: =D19+F19+H19+J19+L19+N19+P19+R19 -> 150 | U19: Medium
A20: Legspreader | B20: f0ecd5 | C20: Tequila | D20: 30 | E20: Vodka | F20: 30 | G20: Gin | H20: 30 | I20: Dark rum | J20: 30 | K20: #shake | L20: 0 | T20: =D20+F20+H20+J20+L20+N20+P20+R20 -> 120 | U20: Rock
A21: Liquid Bubble Gum | B21: FFFFFF | C21: Vodka | D21: 60 | E21: Peach Tree | F21: 60 | G21: Cola | H21: 120 | I21: #stir | J21: 0 | T21: =D21+F21+H21+J21+L21+N21+P21+R21 -> 240 | U21: Big
A22: Desert Sunrise | B22: FFFFFF | C22: #crushed ice | D22: 0 | E22: Vodka | F22: 38 | G22: Orange Juice | H22: 45 | I22: Pineapple juice | J22: 45 | K22: Grenadine syrup | L22: 5 | M22: #stir | N22: 0 | T22: =D22+F22+H22+J22+L22+N22+P22+R22 -> 133 | U22: Medium
A23: Absolute Vacation | B23: FFFFFF | C23: #ice | D23: 0 | E23: Cranberry juice | F23: 30 | G23: Orange Juice | H23: 30 | I23: Pineapple juice | J23: 30 | K23: Vodka | L23: 30 | M23: #shake | N23: 0 | T23: =D23+F23+H23+J23+L23+N23+P23+R23 -> 120 | U23: Medium
A24: Hawaiian Seduction | B24: FFFFFF | C24: #ice | D24: 0 | E24: Tequila | F24: 30 | G24: Lime juice | H24: 180 | I24: Vodka | J24: 30 | K24: #stir | L24: 0 | T24: =D24+F24+H24+J24+L24+N24+P24+R24 -> 240 | U24: Big
A25: Hawaiian Sea Breeze | B25: FFFFFF | C25: #ice | D25: 0 | E25: Vodka | F25: 45 | G25: Pineapple juice | H25: 135 | I25: Cranberry juice | J25: 10 | K25: #stir | L25: 0 | T25: =D25+F25+H25+J25+L25+N25+P25+R25 -> 190 | U25: Big
A26: Island Punch | B26: FFFFFF | C26: #ice | D26: 0 | E26: White rum | F26: 30 | G26: Grenadine syrup | H26: 5 | I26: Orange juice | J26: 120 | K26: Pineapple juice | L26: 120 | M26: #stir | N26: 0 | T26: =D26+F26+H26+J26+L26+N26+P26+R26 -> 275 | U26: Big
A27: Jamaican Sunrise | B27: FFFFFF | C27: Orange juice | D27: 135 | E27: Vodka | F27: 60 | G27: Peach Tree | H27: 60 | I27: #shake | J27: 0 | K27: Cranberry juice | L27: 30 | T27: =D27+F27+H27+J27+L27+N27+P27+R27 -> 285 | U27: Big
A28: Montana Sunrise | B28: FFFFFF | C28: #ice | D28: 0 | E28: Grenadine syrup | F28: 23 | G28: Orange Juice | H28: 60 | I28: Vodka | J28: 120 | K28: #shake | L28: 0 | M28: #strain | N28: 0 | T28: =D28+F28+H28+J28+L28+N28+P28+R28 -> 203 | U28: Big
A29: Pimp Daddy | B29: FFFFFF | C29: #ice | D29: 0 | E29: Tequila | F29: 60 | G29: Vodka | H29: 60 | I29: Lemon juice | J29: 30 | K29: Cranberry juice | L29: 90 | M29: #stir | N29: 0 | T29: =D29+F29+H29+J29+L29+N29+P29+R29 -> 240 | U29: Big
A30: Adam Cocktail | B30: FFFFFF | C30: #ice | D30: 0 | E30: Dark rum | F30: 60 | G30: Lemon juice | H30: 30 | I30: Grenadine syrup | J30: 30 | K30: #shake | L30: 0 | M30: #strain | N30: 0 | T30: =D30+F30+H30+J30+L30+N30+P30+R30 -> 120 | U30: Rock
A31: Long Island Taxi | B31: FFFFFF | C31: #ice | D31: 0 | E31: Vodka | F31: 60 | G31: Gin | H31: 30 | I31: Tequila | J31: 30 | K31: Dark rum | L31: 30 | M31: Orange juice | N31: 60 | O31: #shake | P31: 0 | Q31: #strain | R31: 0 | T31: =D31+F31+H31+J31+L31+N31+P31+R31 -> 210 | U31: Big
A32: Caribe Cosmopolitan | B32: FFFFFF | C32: #ice | D32: 0 | E32: Dark rum | F32: 45 | G32: Cranberry juice | H32: 30 | I32: Triple sec | J32: 30 | K32: Lime juice | L32: 15 | M32: #shake | N32: 0 | T32: =D32+F32+H32+J32+L32+N32+P32+R32 -> 120 | U32: Medium
A33: Key West Screwdriver | B33: FFFFFF | C33: Vodka | D33: 60 | E33: Lime juice | F33: 30 | G33: Orange Juice | H33: 150 | I33: #stir | J33: 0 | T33: =D33+F33+H33+J33+L33+N33+P33+R33 -> 240 | U33: Big
A34: Shark Tank | B34: FFFFFF | C34: Lemonade | D34: 120 | E34: Vodka | F34: 120 | G34: Grenadine syrup | H34: 60 | T34: =D34+F34+H34+J34+L34+N34+P34+R34 -> 300 | U34: Big
A35: A Gilligans Island | B35: FFFFFF | C35: Vodka | D35: 30 | E35: Peach Tree | F35: 30 | G35: Orange Juice | H35: 90 | I35: Cranberry juice | J35: 90 | K35: #shake | L35: 0 | T35: =D35+F35+H35+J35+L35+N35+P35+R35 -> 240 | U35: Big
A36: Blind Bat | B36: FFFFFF | C36: Vodka | D36: 120 | E36: Cola | F36: 120 | G36: White rum | H36: 10 | I36: #stir | J36: 0 | T36: =D36+F36+H36+J36+L36+N36+P36+R36 -> 250 | U36: Big
A37: Hot Sex Cocktail | B37: FFFFFF | C37: #ice | D37: 0 | E37: Triple sec | F37: 75 | G37: Orange Juice | H37: 120 | I37: #stir | J37: 0 | K37: Grenadine syrup | L37: 10 | T37: =D37+F37+H37+J37+L37+N37+P37+R37 -> 205 | U37: Big
A38: Bloody Nightmare | B38: FFFFFF | C38: #ice | D38: 0 | E38: Vodka | F38: 30 | G38: Lime juice | H38: 60 | I38: Cranberry juice | J38: 210 | K38: #stir | L38: 0 | T38: =D38+F38+H38+J38+L38+N38+P38+R38 -> 300 | U38: Big
A39: Snoop Dogg | B39: FFFFFF | C39: Gin | D39: 60 | E39: Orange Juice | F39: 90 | G39: #stir | H39: 0 | T39: =D39+F39+H39+J39+L39+N39+P39+R39 -> 150 | U39: Medium
A40: Gin Citric | B40: FFFFFF | C40: #ice | D40: 0 | E40: Gin | F40: 60 | G40: Grenadine syrup | H40: 5 | I40: Lemon juice | J40: 30 | K40: Lime juice | L40: 30 | M40: Orange juice | N40: 60 | O40: #stir | P40: 0 | T40: =D40+F40+H40+J40+L40+N40+P40+R40 -> 185 | U40: Big
...

Sheet Fluids
A1: Ingredient name | B1: ="/* Written by JelleWho This file stores all data about all the types of drinks */ //Ingredients can NOT have a ""."" or "","" or ""-"" in them!"&CHAR(10)& D1&CHAR(13)&E1 -> /* Written by JelleWho This file stores all data about all the types of drinks */ //Ingredients can NOT have a "." or "," or "-" in them! enum IngredientE {UNK, TRIPLE_SEC, GIN, LIME_JUICE, LEMON_JUICE, LEMONADE, CRANBERRY_JUICE, VODKA, PEACH_TREE, WHITE_RUM, DARK_RUM, TEQUILA, GRENADINE_SYRUP, COLA, SPRITE, ORANGE_JUICE, PINEAPPLE_JUICE}; String IngredientS[] = {"UNK", "TRIPLE_SEC", "GIN", "LIME_JUICE", "LEMON_JUICE", "LEMONADE", "CRANBERRY_JUICE", "VODKA", "PEACH_TREE", "WHITE_RUM", "DARK_RUM", "TEQUILA", "GRENADINE_SYRUP", "COLA", "SPRITE", "ORANGE_JUICE", "PINEAPPLE_JUICE"}; | C1: Ingredient name in code | D1: ="enum IngredientE {UNK, " &D2 & "};" -> enum IngredientE {UNK, TRIPLE_SEC, GIN, LIME_JUICE, LEMON_JUICE, LEMONADE, CRANBERRY_JUICE, VODKA, PEACH_TREE, WHITE_RUM, DARK_RUM, TEQUILA, GRENADINE_SYRUP, COLA, SPRITE, ORANGE_JUICE, PINEAPPLE_JUICE}; | E1: ="String IngredientS[] = {""UNK"", "&E2&"};" -> String IngredientS[] = {"UNK", "TRIPLE_SEC", "GIN", "LIME_JUICE", "LEMON_JUICE", "LEMONADE", "CRANBERRY_JUICE", "VODKA", "PEACH_TREE", "WHITE_RUM", "DARK_RUM", "TEQUILA", "GRENADINE_SYRUP", "COLA", "SPRITE", "ORANGE_JUICE", "PINEAPPLE_JUICE"}; | F1: Times used | G1: =COUNTIF(G2:G17, "PUMP")&"xPUMP "&COUNTIF(G2:G17, "SHOT")&"xSHOT" -> 4xPUMP 12xSHOT | I1: https://www.cocktailbuilder.com/
A2: Triple Sec | B2: 1 | C2: =IF(OR(A2="",A2="."),"",UPPER(SUBSTITUTE(SUBSTITUTE(SUBSTITUTE(SUBSTITUTE(SUBSTITUTE(A2, "'", ""), ",", "_"), ".", "_"), "-", "_")," ", "_"))) -> TRIPLE_SEC | D2: =IF(OR(A2="",A2="."),D3,IF(ROW(A2)>2,", ","")&C2&D3) -> TRIPLE_SEC, GIN, LIME_JUICE, LEMON_JUICE, LEMONADE, CRANBERRY_JUICE, VODKA, PEACH_TREE, WHITE_RUM, DARK_RUM, TEQUILA, GRENADINE_SYRUP, COLA, SPRITE, ORANGE_JUICE, PINEAPPLE_JUICE | E2: =IF(OR(A2="",A2="."),E3,IF(ROW(A2)>2,", ","")&""""&C2&""""&E3) -> "TRIPLE_SEC", "GIN", "LIME_JUICE", "LEMON_JUICE", "LEMONADE", "CRANBERRY_JUICE", "VODKA", "PEACH_TREE", "WHITE_RUM", "DARK_RUM", "TEQUILA", "GRENADINE_SYRUP", "COLA", "SPRITE", "ORANGE_JUICE", "PINEAPPLE_JUICE" | F2: =COUNTIF(Drinks!C2:Q88, A2) -> 11 | G2: SHOT
A3: Gin | B3: =B2+1 -> 2 | C3: =IF(OR(A3="",A3="."),"",UPPER(SUBSTITUTE(SUBSTITUTE(SUBSTITUTE(SUBSTITUTE(SUBSTITUTE(A3, "'", ""), ",", "_"), ".", "_"), "-", "_")," ", "_"))) -> GIN | D3: =IF(OR(A3="",A3="."),D4,IF(ROW(A3)>2,", ","")&C3&D4) -> , GIN, LIME_JUICE, LEMON_JUICE, LEMONADE, CRANBERRY_JUICE, VODKA, PEACH_TREE, WHITE_RUM, DARK_RUM, TEQUILA, GRENADINE_SYRUP, COLA, SPRITE, ORANGE_JUICE, PINEAPPLE_JUICE | E3: =IF(OR(A3="",A3="."),E4,IF(ROW(A3)>2,", ","")&""""&C3&""""&E4) -> , "GIN", "LIME_JUICE", "LEMON_JUICE", "LEMONADE", "CRANBERRY_JUICE", "VODKA", "PEACH_TREE", "WHITE_RUM", "DARK_RUM", "TEQUILA", "GRENADINE_SYRUP", "COLA", "SPRITE", "ORANGE_JUICE", "PINEAPPLE_JUICE" | F3: =COUNTIF(Drinks!C3:Q89, A3) -> 14 | G3: SHOT
A4: Lime juice | B4: =B3+1 -> 3 | C4: =IF(OR(A4="",A4="."),"",UPPER(SUBSTITUTE(SUBSTITUTE(SUBSTITUTE(SUBSTITUTE(SUBSTITUTE(A4, "'", ""), ",", "_"), ".", "_"), "-", "_")," ", "_"))) -> LIME_JUICE | D4: =IF(OR(A4="",A4="."),D5,IF(ROW(A4)>2,", ","")&C4&D5) -> , LIME_JUICE, LEMON_JUICE, LEMONADE, CRANBERRY_JUICE, VODKA, PEACH_TREE, WHITE_RUM, DARK_RUM, TEQUILA, GRENADINE_SYRUP, COLA, SPRITE, ORANGE_JUICE, PINEAPPLE_JUICE | E4: =IF(OR(A4="",A4="."),E5,IF(ROW(A4)>2,", ","")&""""&C4&""""&E5) -> , "LIME_JUICE", "LEMON_JUICE", "LEMONADE", "CRANBERRY_JUICE", "VODKA", "PEACH_TREE", "WHITE_RUM", "DARK_RUM", "TEQUILA", "GRENADINE_SYRUP", "COLA", "SPRITE", "ORANGE_JUICE", "PINEAPPLE_JUICE" | F4: =COUNTIF(Drinks!C4:Q90, A4) -> 10 | G4: SHOT
A5: Lemon juice | B5: =B4+1 -> 4 | C5: =IF(OR(A5="",A5="."),"",UPPER(SUBSTITUTE(SUBSTITUTE(SUBSTITUTE(SUBSTITUTE(SUBSTITUTE(A5, "'", ""), ",", "_"), ".", "_"), "-", "_")," ", "_"))) -> LEMON_JUICE | D5: =IF(OR(A5="",A5="."),D6,IF(ROW(A5)>2,", ","")&C5&D6) -> , LEMON_JUICE, LEMONADE, CRANBERRY_JUICE, VODKA, PEACH_TREE, WHITE_RUM, DARK_RUM, TEQUILA, GRENADINE_SYRUP, COLA, SPRITE, ORANGE_JUICE, PINEAPPLE_JUICE | E5: =IF(OR(A5="",A5="."),E6,IF(ROW(A5)>2,", ","")&""""&C5&""""&E6) -> , "LEMON_JUICE", "LEMONADE", "CRANBERRY_JUICE", "VODKA", "PEACH_TREE", "WHITE_RUM", "DARK_RUM", "TEQUILA", "GRENADINE_SYRUP", "COLA", "SPRITE", "ORANGE_JUICE", "PINEAPPLE_JUICE" | F5: =COUNTIF(Drinks!C5:Q91, A5) -> 7 | G5: SHOT
A6: Lemonade | B6: =B5+1 -> 5 | C6: =IF(OR(A6="",A6="."),"",UPPER(SUBSTITUTE(SUBSTITUTE(SUBSTITUTE(SUBSTITUTE(SUBSTITUTE(A6, "'", ""), ",", "_"), ".", "_"), "-", "_")," ", "_"))) -> LEMONADE | D6: =IF(OR(A6="",A6="."),D7,IF(ROW(A6)>2,", ","")&C6&D7) -> , LEMONADE, CRANBERRY_JUICE, VODKA, PEACH_TREE, WHITE_RUM, DARK_RUM, TEQUILA, GRENADINE_SYRUP, COLA, SPRITE, ORANGE_JUICE, PINEAPPLE_JUICE | E6: =IF(OR(A6="",A6="."),E7,IF(ROW(A6)>2,", ","")&""""&C6&""""&E7) -> , "LEMONADE", "CRANBERRY_JUICE", "VODKA", "PEACH_TREE", "WHITE_RUM", "DARK_RUM", "TEQUILA", "GRENADINE_SYRUP", "COLA", "SPRITE", "ORANGE_JUICE", "PINEAPPLE_JUICE" | F6: =COUNTIF(Drinks!C6:Q92, A6) -> 3 | G6: SHOT | H6: Aanmaak limonade citroen
A7: Cranberry juice | B7: =B6+1 -> 6 | C7: =IF(OR(A7="",A7="."),"",UPPER(SUBSTITUTE(SUBSTITUTE(SUBSTITUTE(SUBSTITUTE(SUBSTITUTE(A7, "'", ""), ",", "_"), ".", "_"), "-", "_")," ", "_"))) -> CRANBERRY_JUICE | D7: =IF(OR(A7="",A7="."),D8,IF(ROW(A7)>2,", ","")&C7&D8) -> , CRANBERRY_JUICE, VODKA, PEACH_TREE, WHITE_RUM, DARK_RUM, TEQUILA, GRENADINE_SYRUP, COLA, SPRITE, ORANGE_JUICE, PINEAPPLE_JUICE | E7: =IF(OR(A7="",A7="."),E8,IF(ROW(A7)>2,", ","")&""""&C7&""""&E8) -> , "CRANBERRY_JUICE", "VODKA", "PEACH_TREE", "WHITE_RUM", "DARK_RUM", "TEQUILA", "GRENADINE_SYRUP", "COLA", "SPRITE", "ORANGE_JUICE", "PINEAPPLE_JUICE" | F7: =COUNTIF(Drinks!C7:Q93, A7) -> 12 | G7: SHOT
A8: Vodka | B8: =B7+1 -> 7 | C8: =IF(OR(A8="",A8="."),"",UPPER(SUBSTITUTE(SUBSTITUTE(SUBSTITUTE(SUBSTITUTE(SUBSTITUTE(A8, "'", ""), ",", "_"), ".", "_"), "-", "_")," ", "_"))) -> VODKA | D8: =IF(OR(A8="",A8="."),D9,IF(ROW(A8)>2,", ","")&C8&D9) -> , VODKA, PEACH_TREE, WHITE_RUM, DARK_RUM, TEQUILA, GRENADINE_SYRUP, COLA, SPRITE, ORANGE_JUICE, PINEAPPLE_JUICE | E8: =IF(OR(A8="",A8="."),E9,IF(ROW(A8)>2,", ","")&""""&C8&""""&E9) -> , "VODKA", "PEACH_TREE", "WHITE_RUM", "DARK_RUM", "TEQUILA", "GRENADINE_SYRUP", "COLA", "SPRITE", "ORANGE_JUICE", "PINEAPPLE_JUICE" | F8: =COUNTIF(Drinks!C8:Q94, A8) -> 24 | G8: SHOT
A9: Peach Tree | B9: =B8+1 -> 8 | C9: =IF(OR(A9="",A9="."),"",UPPER(SUBSTITUTE(SUBSTITUTE(SUBSTITUTE(SUBSTITUTE(SUBSTITUTE(A9, "'", ""), ",", "_"), ".", "_"), "-", "_")," ", "_"))) -> PEACH_TREE | D9: =IF(OR(A9="",A9="."),D10,IF(ROW(A9)>2,", ","")&C9&D10) -> , PEACH_TREE, WHITE_RUM, DARK_RUM, TEQUILA, GRENADINE_SYRUP, COLA, SPRITE, ORANGE_JUICE, PINEAPPLE_JUICE | E9: =IF(OR(A9="",A9="."),E10,IF(ROW(A9)>2,", ","")&""""&C9&""""&E10) -> , "PEACH_TREE", "WHITE_RUM", "DARK_RUM", "TEQUILA", "GRENADINE_SYRUP", "COLA", "SPRITE", "ORANGE_JUICE", "PINEAPPLE_JUICE" | F9: =COUNTIF(Drinks!C9:Q95, A9) -> 3 | G9: SHOT
A10: White rum | B10: =B9+1 -> 9 | C10: =IF(OR(A10="",A10="."),"",UPPER(SUBSTITUTE(SUBSTITUTE(SUBSTITUTE(SUBSTITUTE(SUBSTITUTE(A10, "'", ""), ",", "_"), ".", "_"), "-", "_")," ", "_"))) -> WHITE_RUM | D10: =IF(OR(A10="",A10="."),D11,IF(ROW(A10)>2,", ","")&C10&D11) -> , WHITE_RUM, DARK_RUM, TEQUILA, GRENADINE_SYRUP, COLA, SPRITE, ORANGE_JUICE, PINEAPPLE_JUICE | E10: =IF(OR(A10="",A10="."),E11,IF(ROW(A10)>2,", ","")&""""&C10&""""&E11) -> , "WHITE_RUM", "DARK_RUM", "TEQUILA", "GRENADINE_SYRUP", "COLA", "SPRITE", "ORANGE_JUICE", "PINEAPPLE_JUICE" | F10: =COUNTIF(Drinks!C10:Q96, A10) -> 6 | G10: SHOT
A11: Dark rum | B11: =B10+1 -> 10 | C11: =IF(OR(A11="",A11="."),"",UPPER(SUBSTITUTE(SUBSTITUTE(SUBSTITUTE(SUBSTITUTE(SUBSTITUTE(A11, "'", ""), ",", "_"), ".", "_"), "-", "_")," ", "_"))) -> DARK_RUM | D11: =IF(OR(A11="",A11="."),D12,IF(ROW(A11)>2,", ","")&C11&D12) -> , DARK_RUM, TEQUILA, GRENADINE_SYRUP, COLA, SPRITE, ORANGE_JUICE, PINEAPPLE_JUICE | E11: =IF(OR(A11="",A11="."),E12,IF(ROW(A11)>2,", ","")&""""&C11&""""&E12) -> , "DARK_RUM", "TEQUILA", "GRENADINE_SYRUP", "COLA", "SPRITE", "ORANGE_JUICE", "PINEAPPLE_JUICE" | F11: =COUNTIF(Drinks!C11:Q97, A11) -> 6 | G11: SHOT
A12: Tequila | B12: =B11+1 -> 11 | C12: =IF(OR(A12="",A12="."),"",UPPER(SUBSTITUTE(SUBSTITUTE(SUBSTITUTE(SUBSTITUTE(SUBSTITUTE(A12, "'", ""), ",", "_"), ".", "_"), "-", "_")," ", "_"))) -> TEQUILA | D12: =IF(OR(A12="",A12="."),D13,IF(ROW(A12)>2,", ","")&C12&D13) -> , TEQUILA, GRENADINE_SYRUP, COLA, SPRITE, ORANGE_JUICE, PINEAPPLE_JUICE | E12: =IF(OR(A12="",A12="."),E13,IF(ROW(A12)>2,", ","")&""""&C12&""""&E13) -> , "TEQUILA", "GRENADINE_SYRUP", "COLA", "SPRITE", "ORANGE_JUICE", "PINEAPPLE_JUICE" | F12: =COUNTIF(Drinks!C12:Q98, A12) -> 7 | G12: SHOT
A13: Grenadine syrup | B13: =B12+1 -> 12 | C13: =IF(OR(A13="",A13="."),"",UPPER(SUBSTITUTE(SUBSTITUTE(SUBSTITUTE(SUBSTITUTE(SUBSTITUTE(A13, "'", ""), ",", "_"), ".", "_"), "-", "_")," ", "_"))) -> GRENADINE_SYRUP | D13: =IF(OR(A13="",A13="."),D14,IF(ROW(A13)>2,", ","")&C13&D14) -> , GRENADINE_SYRUP, COLA, SPRITE, ORANGE_JUICE, PINEAPPLE_JUICE | E13: =IF(OR(A13="",A13="."),E14,IF(ROW(A13)>2,", ","")&""""&C13&""""&E14) -> , "GRENADINE_SYRUP", "COLA", "SPRITE", "ORANGE_JUICE", "PINEAPPLE_JUICE" | F13: =COUNTIF(Drinks!C13:Q99, A13) -> 8 | G13: SHOT
A14: Cola | B14: =B13+1 -> 13 | C14: =IF(OR(A14="",A14="."),"",UPPER(SUBSTITUTE(SUBSTITUTE(SUBSTITUTE(SUBSTITUTE(SUBSTITUTE(A14, "'", ""), ",", "_"), ".", "_"), "-", "_")," ", "_"))) -> COLA | D14: =IF(OR(A14="",A14="."),D15,IF(ROW(A14)>2,", ","")&C14&D15) -> , COLA, SPRITE, ORANGE_JUICE, PINEAPPLE_JUICE | E14: =IF(OR(A14="",A14="."),E15,IF(ROW(A14)>2,", ","")&""""&C14&""""&E15) -> , "COLA", "SPRITE", "ORANGE_JUICE", "PINEAPPLE_JUICE" | F14: =COUNTIF(Drinks!C14:Q100, A14) -> 4 | G14: PUMP
A15: Sprite | B15: =B14+1 -> 14 | C15: =IF(OR(A15="",A15="."),"",UPPER(SUBSTITUTE(SUBSTITUTE(SUBSTITUTE(SUBSTITUTE(SUBSTITUTE(A15, "'", ""), ",", "_"), ".", "_"), "-", "_")," ", "_"))) -> SPRITE | D15: =IF(OR(A15="",A15="."),D16,IF(ROW(A15)>2,", ","")&C15&D16) -> , SPRITE, ORANGE_JUICE, PINEAPPLE_JUICE | E15: =IF(OR(A15="",A15="."),E16,IF(ROW(A15)>2,", ","")&""""&C15&""""&E16) -> , "SPRITE", "ORANGE_JUICE", "PINEAPPLE_JUICE" | F15: =COUNTIF(Drinks!C15:Q101, A15) -> 1 | G15: PUMP
A16: Orange Juice | B16: =B15+1 -> 15 | C16: =IF(OR(A16="",A16="."),"",UPPER(SUBSTITUTE(SUBSTITUTE(SUBSTITUTE(SUBSTITUTE(SUBSTITUTE(A16, "'", ""), ",", "_"), ".", "_"), "-", "_")," ", "_"))) -> ORANGE_JUICE | D16: =IF(OR(A16="",A16="."),D17,IF(ROW(A16)>2,", ","")&C16&D17) -> , ORANGE_JUICE, PINEAPPLE_JUICE | E16: =IF(OR(A16="",A16="."),E17,IF(ROW(A16)>2,", ","")&""""&C16&""""&E17) -> , "ORANGE_JUICE", "PINEAPPLE_JUICE" | F16: =COUNTIF(Drinks!C16:Q102, A16) -> 14 | G16: PUMP
A17: Pineapple juice | B17: =B16+1 -> 16 | C17: =IF(OR(A17="",A17="."),"",UPPER(SUBSTITUTE(SUBSTITUTE(SUBSTITUTE(SUBSTITUTE(SUBSTITUTE(A17, "'", ""), ",", "_"), ".", "_"), "-", "_")," ", "_"))) -> PINEAPPLE_JUICE | D17: =IF(OR(A17="",A17="."),D18,IF(ROW(A17)>2,", ","")&C17&D18) -> , PINEAPPLE_JUICE | E17: =IF(OR(A17="",A17="."),E18,IF(ROW(A17)>2,", ","")&""""&C17&""""&E18) -> , "PINEAPPLE_JUICE" | F17: =COUNTIF(Drinks!C17:Q103, A17) -> 4 | G17: PUMP

Sheet Glasses & #s
A1: Glass type | B1: Content (ml) | C1: Content (oz) | G1: #stir | H1: Stir around with barspoon in glass
A2: Big glass | B2: 300 | C2: 10 | D2: https://www.ikea.com/nl/nl/p/pokal-glas-helder-glas-10270478/ | E2: 35cl | G2: #blend | H2: Pour drink over a few times from shaker to glass
A3: Medium glass | B3: 180 | C3: 6 | D3: https://www.ikea.com/nl/nl/p/pokal-glas-helder-glas-30288241/ | E3: 37cl | G3: #shake | H3: Shake in shaker, after that pour in glass
A4: Rock glass | B4: 120 | C4: 4 | G4: #strain | H4: Pour in glass with strainer

Sheet Calc
B1: X
A2: First dispensers | B2: 200
B3: =B2+B$9 -> 4180
B4: =B3+B$9 -> 8160
B5: =B4+B$9 -> 12140
B6: =B5+B$9 -> 16120
A7: Last dispensers | B7: 20100
A8: Pump/home | B8: =B7+B$9 -> 24080
A9: Between two dispensers | B9: =(B7-B2)/5 -> 3980

Sheet Led section
A1: len | B1: 10
A2: TotalLEDs | B2: 100
A3: BedSize_X | B3: 23900
A5: LocationX | B5: 0 | C5: 3500 | D5: 7625 | E5: 11750 | F5: 15875 | G5: 20000 | H5: 23900
B7: =ROUNDDOWN((B5*$B2)/$B3,0) -> 0 | C7: =ROUNDDOWN((C5*$B2)/$B3,0) -> 14 | D7: =ROUNDDOWN((D5*$B2)/$B3,0) -> 31 | E7: =ROUNDDOWN((E5*$B2)/$B3,0) -> 49 | F7: =ROUNDDOWN((F5*$B2)/$B3,0) -> 66 | G7: =ROUNDDOWN((G5*$B2)/$B3,0) -> 83 | H7: =ROUNDDOWN((H5*$B2)/$B3,0) -> 100
A11: LEDPos
A15: 0 | B15: ="i"&A15&"=VODKA&m"&A15&"=10" -> i0=VODKA&m0=10
A16: 1 | B16: ="i"&A16&"=VODKA&m"&A16&"=10" -> i1=VODKA&m1=10
A17: =A16+1 -> 2 | B17: ="i"&A17&"=VODKA&m"&A17&"=10" -> i2=VODKA&m2=10
A18: =A17+1 -> 3 | B18: ="i"&A18&"=VODKA&m"&A18&"=10" -> i3=VODKA&m3=10
A19: =A18+1 -> 4 | B19: ="i"&A19&"=VODKA&m"&A19&"=10" -> i4=VODKA&m4=10
A20: =A19+1 -> 5 | B20: ="i"&A20&"=VODKA&m"&A20&"=10" -> i5=VODKA&m5=10
A21: =A20+1 -> 6 | B21: ="i"&A21&"=VODKA&m"&A21&"=10" -> i6=VODKA&m6=10
A22: =A21+1 -> 7 | B22: ="i"&A22&"=VODKA&m"&A22&"=10" -> i7=VODKA&m7=10
B23: =_xlfn.CONCAT("http://192.168.1.200/set?m=test&",B15,B16,B17,B18,B19,B20,B21,B22) -> http://192.168.1.200/set?m=test&i0=VODKA&m0=10i1=VODKA&m1=10i2=VODKA&m2=10i3=VODKA&m3=10i4=VODKA&m4=10i5=VODKA&m5=10i6=VODKA&m6=10i7=VODKA&m7=10

Sheet Calibrate msml
B1: Now | C1: Desired | E1: Ml at beginning | F1: ml dispensed | G1: Desmos plot
A2: ML actual | B2: =AVERAGE(F2:F12) -> 52.727273 | C2: 50 | E2: 700 | F2: 46 | G2: ="["&"("&E2&","&F2&")"&IF(G3="","",","&G3)&"]" -> [(700,46),(654,50),(604,53),(551,53),(498,54),(444,54),(390,55),(335,55),(280,54),(226,54),(172,52)]
A3: MS/ML | B3: 42 | C3: =ROUND((B3/B2)*C2,1) -> 39.8 | E3: =E2-F2 -> 654 | F3: 50 | G3: ="("&E3&","&F3&")"&IF(G4="","",","&G4) -> (654,50),(604,53),(551,53),(498,54),(444,54),(390,55),(335,55),(280,54),(226,54),(172,52)
C4: =ROUND(B2/B3*C3,2) -> 49.97 | E4: =E3-F3 -> 604 | F4: 53 | G4: ="("&E4&","&F4&")"&IF(G5="","",","&G5) -> (604,53),(551,53),(498,54),(444,54),(390,55),(335,55),(280,54),(226,54),(172,52)
E5: =E4-F4 -> 551 | F5: 53 | G5: ="("&E5&","&F5&")"&IF(G6="","",","&G6) -> (551,53),(498,54),(444,54),(390,55),(335,55),(280,54),(226,54),(172,52)
B6: Now | C6: Desired | E6: =E5-F5 -> 498 | F6: 54 | G6: ="("&E6&","&F6&")"&IF(G7="","",","&G7) -> (498,54),(444,54),(390,55),(335,55),(280,54),(226,54),(172,52)
A7: ML actual | B7: =AVERAGE(F14:F19) -> 98.833333 | C7: 100 | E7: =E6-F6 -> 444 | F7: 54 | G7: ="("&E7&","&F7&")"&IF(G8="","",","&G8) -> (444,54),(390,55),(335,55),(280,54),(226,54),(172,52)
A8: MS/ML | B8: 45 | C8: =ROUND((B8/B7)*C7,1) -> 45.5 | E8: =E7-F7 -> 390 | F8: 55 | G8: ="("&E8&","&F8&")"&IF(G9="","",","&G9) -> (390,55),(335,55),(280,54),(226,54),(172,52)
C9: =ROUND(B7/B8*C8,2) -> 99.93 | E9: =E8-F8 -> 335 | F9: 55 | G9: ="("&E9&","&F9&")"&IF(G10="","",","&G10) -> (335,55),(280,54),(226,54),(172,52)
E10: =E9-F9 -> 280 | F10: 54 | G10: ="("&E10&","&F10&")"&IF(G11="","",","&G11) -> (280,54),(226,54),(172,52)
B11: Now | C11: Desired | E11: =E10-F10 -> 226 | F11: 54 | G11: ="("&E11&","&F11&")"&IF(G12="","",","&G12) -> (226,54),(172,52)
A12: ML actual | B12: =AVERAGE(F21:F24) -> 145 | C12: 150 | E12: =E11-F11 -> 172 | F12: 52 | G12: ="("&E12&","&F12&")"&IF(G13="","",","&G13) -> (172,52)
A13: MS/ML | B13: 42 | C13: =ROUND((B13/B12)*C12,1) -> 43.4
C14: =ROUND(B12/B13*C13,2) -> 149.83 | E14: 700 | F14: 90 | G14: ="["&"("&E14&","&F14&")"&IF(G15="","",","&G15)&"]" -> [(700,90),(610,99),(511,101),(410,102),(308,102),(206,99)]
E15: =E14-F14 -> 610 | F15: 99 | G15: ="("&E15&","&F15&")"&IF(G16="","",","&G16) -> (610,99),(511,101),(410,102),(308,102),(206,99)
B16: Now | C16: Desired | E16: =E15-F15 -> 511 | F16: 101 | G16: ="("&E16&","&F16&")"&IF(G17="","",","&G17) -> (511,101),(410,102),(308,102),(206,99)
A17: ML actual | B17: =AVERAGE(F26:F28) -> 192.33333 | C17: 200 | E17: =E16-F16 -> 410 | F17: 102 | G17: ="("&E17&","&F17&")"&IF(G18="","",","&G18) -> (410,102),(308,102),(206,99)
A18: MS/ML | B18: 45 | C18: =ROUND((B18/B17)*C17,1) -> 46.8 | E18: =E17-F17 -> 308 | F18: 102 | G18: ="("&E18&","&F18&")"&IF(G19="","",","&G19) -> (308,102),(206,99)
C19: =ROUND(B17/B18*C18,2) -> 200.03 | E19: =E18-F18 -> 206 | F19: 99 | G19: ="("&E19&","&F19&")"&IF(G20="","",","&G20) -> (206,99)
A21: dispenserSettings.FluidLevel | B21: 700 | E21: 700 | F21: 139 | G21: ="["&"("&E21&","&F21&")"&IF(G22="","",","&G22)&"]" -> [(700,139),(561,149),(412,143),(269,149)]
A22: Dispensing | B22: 200 | E22: =E21-F21 -> 561 | F22: 149 | G22: ="("&E22&","&F22&")"&IF(G23="","",","&G23) -> (561,149),(412,143),(269,149)
A23: TimeMSML | B23: 46 | E23: =E22-F22 -> 412 | F23: 143 | G23: ="("&E23&","&F23&")"&IF(G24="","",","&G24) -> (412,143),(269,149)
A24: raw delay | B24: =B23*B22 -> 9200 | E24: =E23-F23 -> 269 | F24: 149 | G24: ="("&E24&","&F24&")"&IF(G25="","",","&G25) -> (269,149)
A25: Compensation factor | B25: =-(((269 / 200) - 1) / (700 - 300)) * (B21 - 300) + 1 -> 0.655
A26: Compensated delay | B26: =B25*B24 -> 6026 | E26: 700 | F26: 183 | G26: ="["&"("&E26&","&F26&")"&IF(G27="","",","&G27)&"]" -> [(700,183),(517,195),(322,199)]
E27: =E26-F26 -> 517 | F27: 195 | G27: ="("&E27&","&F27&")"&IF(G28="","",","&G28) -> (517,195),(322,199)
E28: =E27-F27 -> 322 | F28: 199 | G28: ="("&E28&","&F28&")"&IF(G43="","",","&G43) -> (322,199)
